Workbook
Name BBSpread: WACC!$C$19
Name Beta: WACC!$C$16
Name Beta_2yDaily: WACC!$C$9
Name Beta_Blume: WACC!$C$8
Name Beta_BU_Relev: WACC!$C$15
Name Beta_BU_Unlev: WACC!$C$10
Name Beta_Raw: WACC!$C$7
Name BookEquityJun: Valuation!$C$17
Name Br_Cash: Valuation!$C$34
Name Br_Debt: Valuation!$C$33
Name Br_UTP: Valuation!$C$35
Name BuybackPxMode: Inputs!$E$12
Name CashJun: Valuation!$C$14
Name CashRate: Inputs!$E$15
Name CircSwitch: Inputs!$E$8
Name CommitFee: Inputs!$E$18
Name Comps_EV_High: Comps!$F$30
Name Comps_EV_Low: Comps!$D$30
Name Comps_EV_Value: Comps!$E$30
Name Comps_PE_High: Comps!$F$31
Name Comps_PE_Low: Comps!$D$31
Name Comps_PE_Value: Comps!$E$31
Name Coupon_Notes29: Inputs!$E$21
Name Coupon_Notes31: Inputs!$E$22
Name Coverage26: WACC!$C$22
Name DCF_Base: Valuation!$C$66
Name DCF_Bear: Valuation!$C$68
Name DCF_Bull: Valuation!$C$67
Name DCF_PW: Valuation!$C$69
Name DE_Market: WACC!$C$13
Name DebtFace: WACC!$C$11
Name Dilution: Inputs!$E$27
Name DTAYears: Valuation!$C$12
Name Eq_Jun: Valuation!$C$36
Name Eq_Sep: Valuation!$C$37
Name ERP: WACC!$C$6
Name EV_DCF: Valuation!$C$31
Name ExcessToBuybacks: Inputs!$E$11
Name ExitMultiple: Valuation!$C$9
Name FCFF_2035: Valuation!$C$20
Name FCFF_TV: Valuation!$C$21
Name FeeAmort: Inputs!$E$25
Name GMShift: Sensitivity!$C$6
Name GrowthShift: Sensitivity!$C$5
Name H2Share: Valuation!$C$11
Name HD_Carrying: HEYDUDE!$C$30
Name HD_Cash: HEYDUDE!$C$6
Name HD_CorpAlloc: HEYDUDE!$C$25
Name HD_CumNOPAT: HEYDUDE!$C$14
Name HD_Destroyed: HEYDUDE!$C$22
Name HD_Destroyed_PS: HEYDUDE!$C$23
Name HD_EBITDA21: HEYDUDE!$C$9
Name HD_EBITDA26: HEYDUDE!$C$19
Name HD_EntryMult: HEYDUDE!$C$10
Name HD_FV: HEYDUDE!$C$29
Name HD_Goodwill0: HEYDUDE!$C$11
Name HD_Headline: HEYDUDE!$C$5
Name HD_Headroom: HEYDUDE!$C$31
Name HD_Impair25: HEYDUDE!$C$12
Name HD_Mult_Today: HEYDUDE!$C$20

Sheet Cover
B2: Crocs, Inc. (NASDAQ: CROX)
B3: Valuation model: three statements, DCF, comps, LBO and merger analysis
B4: Prepared by Sidhant Thalor | Valuation date 30-Sep-2026 | US$ millions unless stated
B6: Summary
B7: Rating | C7: =Rating -> BUY
B8: 12-month price target | C8: =PriceTarget -> 190
B9: Upside to price target | C9: =PT_Upside -> 0.60283449
B10: DCF value per share (live scenario) | C10: =ValuePerShare -> 222.98832
B11: Probability-weighted DCF value | C11: =DCF_PW -> 206.89506
B12: Share price (30-Sep-2026) | C12: =SharePrice -> 118.54
B13: Basic shares outstanding (m) | C13: =SharesOut -> 47.945
B14: Market capitalisation | C14: =SharePrice*SharesOut -> 5683.4003
B15: Net debt FY25A (excl. leases) | C15: =Debt!$I$54 -> 1100.531
B16: Enterprise value | C16: =SharePrice*SharesOut+Debt!$I$54 -> 6783.9313
B17: EV / EBITDA FY26E | C17: =(SharePrice*SharesOut+Debt!$I$54)/IS!$J$33 -> 6.9935135
B18: P / E FY26E (adjusted) | C18: =SharePrice/IS!$J$39 -> 8.2064617
B19: FCF yield FY26E | C19: =CF!$J$37/(SharePrice*SharesOut) -> 0.1280283
B20: Scenario shown | C20: =CHOOSE(Scenario,"Base","Bull","Bear") -> Base
B21: Balance sheet check | C21: =IF(MasterCheck=0,"OK","Error") -> OK
B23: Contents
B24: Dashboard | D24: Key outputs, FY26E vs guidance, scenario comparison
B25: Valuation | D25: Terminal value, equity bridge, other methods, SOTP, price target
B26: Football_Field | D26: Value per share by method
B27: Inputs | D27: Scenario switch and forecast drivers
B28: Rev_Build | D28: Revenue by brand, region and channel
B29: IS / BS / CF | D29: Integrated financial statements
B30: NWC / Fixed_Assets / Tax | D30: Supporting schedules
B31: Debt / Equity | D31: Debt schedule, cash sweep, buybacks and share count
B32: WACC / DCF / Sensitivity | D32: Cost of capital, DCF and sensitivity tables
B33: Comps / Precedents | D33: Trading comparables and precedent transactions
B34: LBO / LBO_CF | D34: Leveraged buyout returns
B35: HEYDUDE | D35: Acquisition returns and impairment test
... B37: Hist | D37: Historical financials as reported
B39: Colour code
C40: 1,234.5 | D40: Hard-coded input or historical data
C41: 1,234.5 | D41: Formula
C42: 1,234.5 | D42: Link to another sheet
B44: Interest is on average balances (circular; iterative calculation is on). Set Inputs!CircSwitch to 0 to break the loop.

Sheet Dashboard
B1: Dashboard - operating model outputs
B2: Crocs, Inc. (NASDAQ: CROX) | US$ millions unless stated
B4: Fiscal year ending 31-Dec | C4: Unit | E4: FY2021A | F4: FY2022A | G4: FY2023A | H4: FY2024A | I4: FY2025A | J4: FY2026E | K4: FY2027E | L4: FY2028E | M4: FY2029E | N4: FY2030E | O4: FY2031E | P4: FY2032E | Q4: FY2033E | R4: FY2034E | S4: FY2035E
B6: Scenario override (used by the scenario table - leave at 0) | E6: 0
B7: Key outputs
B8: Revenue | E8: =IS!E7 -> 2313.416 | F8: =IS!F7 -> 3554.985 | G8: =IS!G7 -> 3962.347 | H8: =IS!H7 -> 4102.108 | I8: =IS!I7 -> 4040.647 | J8: =IS!J7 -> 4104.026 | K8: =IS!K7 -> 4247.9569 | L8: =IS!L7 -> 4423.3961 | ... S8: =IS!S7 -> 5624.6101
B9: growth | E9: =IS!E8 -> 0 | F9: =IS!F8 -> 0.53668212 | G9: =IS!G8 -> 0.11458895 | H9: =IS!H8 -> 0.035272277 | I9: =IS!I8 -> -0.014982784 | J9: =IS!J8 -> 0.015685357 | K9: =IS!K8 -> 0.035070669 | L9: =IS!L8 -> 0.041299662 | ... S9: =IS!S8 -> 0.028536689
B10: Crocs brand revenue | E10: =Rev_Build!E17 -> 2313.416 | F10: =Rev_Build!F17 -> 2659.125 | G10: =Rev_Build!G17 -> 3012.954 | H10: =Rev_Build!H17 -> 3277.967 | I10: =Rev_Build!I17 -> 3325.807 | J10: =Rev_Build!J17 -> 3409.3535 | K10: =Rev_Build!K17 -> 3554.0852 | L10: =Rev_Build!L17 -> 3722.1444 | ... S10: =Rev_Build!S17 -> 4792.4506
B11: HEYDUDE revenue | E11: =Rev_Build!E24 -> 0 | F11: =Rev_Build!F24 -> 895.86 | G11: =Rev_Build!G24 -> 949.393 | H11: =Rev_Build!H24 -> 824.141 | I11: =Rev_Build!I24 -> 714.84 | J11: =Rev_Build!J24 -> 694.67245 | K11: =Rev_Build!K24 -> 693.87172 | L11: =Rev_Build!L24 -> 701.25169 | ... S11: =Rev_Build!S24 -> 832.15955
B12: Gross margin | E12: =IS!E11 -> 0.61390602 | F12: =IS!F11 -> 0.52328828 | G12: =IS!G11 -> 0.55775277 | H12: =IS!H11 -> 0.58756571 | I12: =IS!I11 -> 0.58333604 | J12: =IS!J11 -> 0.57783944 | K12: =IS!K11 -> 0.58059836 | L12: =IS!L11 -> 0.58304949 | ... S12: =IS!S11 -> 0.58484855
B13: Management EBIT margin | E13: =IS!E38 -> 0.30053479 | F13: =IS!F38 -> 0.2774504 | G13: =IS!G38 -> 0.27726925 | H13: =IS!H38 -> 0.25602885 | I13: =IS!I38 -> 0.22290168 | J13: =IS!J38 -> 0.22352981 | K13: =IS!K38 -> 0.22847706 | L13: =IS!L38 -> 0.2330192 | ... S13: =IS!S38 -> 0.23819081
B14: Analyst EBIT margin | E14: =IS!E36 -> 0.29801212 | F14: =IS!F36 -> 0.2675654 | G14: =IS!G36 -> 0.26476606 | H14: =IS!H36 -> 0.2549889 | I14: =IS!I36 -> 0.21967522 | J14: =IS!J36 -> 0.21752981 | K14: =IS!K36 -> 0.22447706 | L14: =IS!L36 -> 0.2290192 | ... S14: =IS!S36 -> 0.23419081
B15: EBITDA | E15: =IS!E33 -> 715.04 | F15: =IS!F33 -> 889.985 | G15: =IS!G33 -> 1100.374 | H15: =IS!H33 -> 1115.833 | I15: =IS!I33 -> 966.912 | J15: =IS!J33 -> 970.03191 | K15: =IS!K33 -> 1031.2553 | L15: =IS!L33 -> 1091.2857 | ... S15: =IS!S33 -> 1410.3925
B16: Adjusted diluted EPS (US$) | E16: =IS!E39 -> 8.3153269 | F16: =IS!F39 -> 10.923588 | G16: =IS!G39 -> 12.034785 | H16: =IS!H39 -> 13.167903 | I16: =IS!I39 -> 12.597403 | J16: =IS!J39 -> 14.444715 | K16: =IS!K39 -> 17.050403 | L16: =IS!L39 -> 20.208268 | ... S16: =IS!S39 -> 57.035882
B17: GAAP diluted EPS (US$) | E17: =IS!E25 -> 11.389152 | F17: =IS!F25 -> 8.7113989 | G17: =IS!G25 -> 12.793227 | H17: =IS!H25 -> 15.878995 | I17: =IS!I25 -> -1.497897 | J17: =IS!J25 -> 13.171743 | K17: =IS!K25 -> 15.91723 | L17: =IS!L25 -> 18.876946 | ... S17: =IS!S25 -> 53.316132
B18: Free cash flow | E18: =CF!E37 -> 511.249 | F18: =CF!F37 -> 498.952 | G18: =CF!G37 -> 814.819 | H18: =CF!H37 -> 923.139 | I18: =CF!I37 -> 659.2 | J18: =CF!J37 -> 727.63606 | K18: =CF!K37 -> 789.21823 | L18: =CF!L37 -> 844.47355 | ... S18: =CF!S37 -> 1098.52
B19: Share repurchases | E19: =-CF!E29 -> 1000 | F19: =-CF!F29 -> 0 | G19: =-CF!G29 -> 175.019 | H19: =-CF!H29 -> 552.451 | I19: =-CF!I29 -> 582.32 | J19: =-CF!J29 -> 582.10885 | K19: =-CF!K29 -> 631.37459 | L19: =-CF!L29 -> 675.57884 | ... S19: =-CF!S29 -> 1098.52
B20: Net debt | E20: =Debt!E54 -> 558.193 | F20: =Debt!F54 -> 2130.76 | G20: =Debt!G54 -> 1515.036 | H20: =Debt!H54 -> 1168.854 | I20: =Debt!I54 -> 1100.531 | J20: =Debt!J54 -> 964.00379 | K20: =Debt!K54 -> 815.16014 | L20: =Debt!L54 -> 655.26543 | ... S20: =Debt!S54 -> 550
B21: Net debt / EBITDA | E21: =Debt!E55 -> 0.78064584 | F21: =Debt!F55 -> 2.3941527 | G21: =Debt!G55 -> 1.3768373 | H21: =Debt!H55 -> 1.047517 | I21: =Debt!I55 -> 1.1381915 | J21: =Debt!J55 -> 0.99378565 | K21: =Debt!K55 -> 0.79045425 | L21: =Debt!L55 -> 0.6004527 | ... S21: =Debt!S55 -> 0.38996238
B22: Diluted shares (m) | E22: =IS!E24 -> 63.718 | F22: =IS!F24 -> 62.006 | G22: =IS!G24 -> 61.952 | H22: =IS!H24 -> 59.832 | I22: =IS!I24 -> 54.208 | J22: =IS!J24 -> 48.344673 | K22: =IS!K24 -> 43.966801 | L22: =IS!L24 -> 39.93889 | ... S22: =IS!S24 -> 18.718461
B23: FY2026E vs management guidance (30-Jul-2026)
B24: Revenue growth | J24: =IS!J8 -> 0.015685357
B25: within guidance? | J25: =IF(AND(J24>=0.01-0.0005,J24<=0.02+0.0005),"Yes","No") -> Yes
B26: Crocs brand growth | J26: =Rev_Build!J18 -> 0.025120682
B27: within guidance? | J27: =IF(AND(J26>=0.02-0.0005,J26<=0.03+0.0005),"Yes","No") -> Yes
B28: HEYDUDE growth | J28: =Rev_Build!J25 -> -0.028212677
B29: within guidance? | J29: =IF(AND(J28>=-0.04-0.0005,J28<=-0.02+0.0005),"Yes","No") -> Yes
B30: Management (adjusted) EBIT margin | J30: =IS!J38 -> 0.22352981
B31: within guidance? | J31: =IF(AND(J30>=0.223-0.0005,J30<=0.235+0.0005),"Yes","No") -> Yes
B32: GAAP effective tax rate | J32: =IS!J22 -> 0.23
B33: within guidance? | J33: =IF(AND(J32>=0.225-0.0005,J32<=0.235+0.0005),"Yes","No") -> Yes
B34: Adjusted diluted EPS (US$) | J34: =IS!J39 -> 14.444715
B35: within guidance? | J35: =IF(AND(J34>=13.7-0.0005,J34<=14+0.0005),"Yes","No") -> No
B36: Memo: model FY26 diluted shares (m) | J36: =IS!J24 -> 48.344673
B37: Memo: diluted shares implied by guidance-midpoint EPS | J37: =IS!J39*IS!J24/13.85 -> 50.420579
B39: Scenario comparison (data table)
B40: Scenario | E40: Input | F40: FY26E revenue | G40: FY30E revenue | H40: FY25-30 revenue CAGR | I40: FY30E mgmt EBIT margin | J40: FY26E adj. EPS | K40: FY30E adj. EPS | L40: FY26-30 cumulative FCF | M40: FY30E net debt / EBITDA | N40: DCF value / share | O40: Upside to DCF value
B41: Live model (current selection) | F41: =IS!$J$7 -> 4104.026 | G41: =IS!$N$7 -> 4785.326 | H41: =(IS!$N$7/IS!$I$7)^(1/5)-1 -> 0.034408604 | I41: =IS!$N$38 -> 0.23698135 | J41: =IS!$J$39 -> 14.444715 | K41: =IS!$N$39 -> 27.708377 | L41: =SUM(CF!$J$37:$N$37) -> 4182.3202 | M41: =Debt!$N$55 -> 0.46036728 | N41: =ValuePerShare -> 222.98832 | O41: =Upside -> 0.88112298
B42: Base | E42: 1 | F42: 4104.026 | G42: 4785.326 | H42: 0.034408604 | I42: 0.23698135 | J42: 14.444715 | K42: 27.708377 | L42: 4182.3202 | M42: 0.46036728 | N42: 222.98832 | O42: 0.88112298
B43: Bull | E43: 2 | F43: 4188.2022 | G43: 5321.6687 | H43: 0.056621358 | I43: 0.26507681 | J43: 15.583661 | K43: 35.941766 | L43: 4961.7524 | M43: 0.37296963 | N43: 306.6416 | O43: 1.5868196
...

Sheet Valuation
B1: Valuation summary & price target
B2: Crocs, Inc. (NASDAQ: CROX) | US$ millions unless stated
B4: Terminal-value and bridge assumptions
B5: Terminal growth - Base | C5: 0.025 | D5: Long-run nominal growth for a mature brand
B6: Terminal growth - Bull | C6: 0.03
B7: Terminal growth - Bear | C7: 0.01 | D7: A shrinking brand cannot grow at GDP forever
B8: Terminal growth - live scenario | C8: =CHOOSE(Scenario,TG_Base,TG_Bull,TG_Bear) -> 0.025
B9: Exit EV / EBITDA (cross-check method) | C9: 8 | D9: US GAAP basis; Crocs trades ~7x, developed peers ~9x
B10: Terminal cash tax rate | C10: 0.22 | D10: IP step-up shield has expired by then
B11: H2 share of FY26 free cash flow | C11: 0.668 | D11: FY23-25 average (quarterly data)
B12: Years to realise the residual deferred tax asset | C12: 10
B13: Roll-forward from 30-Jun to 30-Sep (years) | C13: 0.25
B14: Cash at 30-Jun-2026 | C14: 170.276 | D14: 10-Q Q2-26
B15: Long-term income taxes payable (uncertain tax positions) | C15: 639.58 | D15: 10-Q Q2-26 - a debt-like claim most models miss
B16: Share of UTP treated as debt | C16: 1 | D16: 100% = conservative
B17: Book equity at 30-Jun-2026 | C17: 1384.674 | D17: For residual income
B18: Diluted shares (m) | C18: =SharesOut+Dilution -> 48.345
B19: Terminal value
B20: FY35E FCFF | C20: =DCF!$S$17 -> 1078.8535
B21: FCFF normalised for terminal tax rate | C21: =FCFF_2035-DCF!$S$8*(TaxTV-Inputs!$S$103) -> 1026.1642
B22: Discount period to end-FY35 (years) | C22: =DCF!$S$21+0.5 -> 9.5
B23: Terminal value - Gordon growth | C23: =FCFF_TV*(1+TG)/(WACC-TG) -> 14968.19
B24: Terminal value - exit multiple | C24: =DCF!$S$24*ExitMultiple -> 11283.14
B25: Implied exit multiple in Gordon TV | C25: =TV_Gordon/DCF!$S$24 -> 10.612784
B26: Implied perpetual growth in exit-multiple TV | C26: =(TV_Exit*WACC-FCFF_TV)/(TV_Exit+FCFF_TV) -> 0.003963116
B27: Enterprise value -> equity value (Gordon, primary)
B28: PV of FCFF H2-26 to FY35 | C28: =SUM(DCF!$J$23:$S$23) -> 5883.3969
B29: PV of terminal value | C29: =TV_Gordon*(1+WACC)^-N_End -> 6305.4644
B30: PV of residual deferred-tax-asset shield after FY35 | C30: =Tax!$S$15/DTAYears*(1-(1+WACC)^-DTAYears)/WACC*(1+WACC)^-N_End -> 130.54831
B31: Enterprise value | C31: =PV_Explicit+PV_TV+PV_DTA -> 12319.41
B32: terminal value share of EV | C32: =PV_TV/EV_DCF -> 0.5118317
B33: Less: debt (face) | C33: =-DebtFace -> -1334
B34: Plus: cash | C34: =CashJun -> 170.276
B35: Less: uncertain tax positions | C35: =-UTP*UTPPct -> -639.58
B36: Equity value at 30-Jun-2026 | C36: =EV_DCF+Br_Debt+Br_Cash+Br_UTP -> 10516.106
B37: Equity value rolled to 30-Sep-2026 | C37: =Eq_Jun*(1+Ke)^RollFwd -> 10780.37
B38: DCF value per share (US$) | C38: =Eq_Sep/SharesDil -> 222.98832
B39: upside / (downside) vs share price | C39: =ValuePerShare/SharePrice-1 -> 0.88112298
B40: Cross-check: value per share, exit-multiple TV | C40: =((PV_Explicit+TV_Exit*(1+WACC)^-N_End+PV_DTA)+Br_Debt+Br_Cash+Br_UTP)*(1+Ke)^RollFwd/SharesDil -> 190.07146
B41: Implied EV / FY26E EBITDA at DCF value | C41: =EV_DCF/IS!$J$33 -> 12.700004
...

Sheet Football_Field
B1: Valuation football field (US$ per share)
B2: Crocs, Inc. (NASDAQ: CROX) | US$ millions unless stated
B5: Method | C5: Low | D5: High | E5: Range (chart)
B6: 52-week trading range | C6: 73.39 | D6: 141.19 | E6: =MAX(0,D6-C6) -> 67.8
B7: Analyst price targets (consensus low-high) | C7: 95 | D7: 163 | E7: =MAX(0,D7-C7) -> 68
B8: Trading comps - EV/EBITDA (IFRS 16), 25th-75th | C8: =Comps_EV_Low -> 144.05876 | D8: =Comps_EV_High -> 179.6987 | E8: =MAX(0,D8-C8) -> 35.639936
B9: Trading comps - forward P/E, 25th-75th | C9: =Comps_PE_Low -> 173.61888 | D9: =Comps_PE_High -> 225.18999 | E9: =MAX(0,D9-C9) -> 51.571106
B10: Precedent transactions (control), 25th-75th | C10: =Prec_Low -> 163.60386 | D10: =Prec_High -> 213.43353 | E10: =MAX(0,D10-C10) -> 49.829665
B11: LBO - price for a 25% to 20% sponsor IRR | C11: =LBO_Px25 -> 135.47043 | D11: =LBO_Px20 -> 149.63484 | E11: =MAX(0,D11-C11) -> 14.164415
B12: DCF - Bear to Bull scenario | C12: =DCF_Bear -> 113.57526 | D12: =DCF_Bull -> 306.6416 | E12: =MAX(0,D12-C12) -> 193.06634
B13: DCF - Base, WACC +/-1%, growth +/-0.5% | C13: =MIN(Sensitivity!D11:F15) -> 184.78568 | D13: =MAX(Sensitivity!D11:F15) -> 281.09757 | E13: =MAX(0,D13-C13) -> 96.311885
B15: Current share price | C15: =SharePrice -> 118.54
B16: Price target | C16: =PriceTarget -> 190
B17: Rating | C17: =Rating -> BUY
B18: ="Value per share by method (US$) | price "&TEXT(SharePrice,"$0.00")&" | price target "&TEXT(PriceTarget,"$0") -> Value per share by method (US$) | price $118.54 | price target $190

Sheet Inputs
B1: Inputs & scenarios
B2: Crocs, Inc. (NASDAQ: CROX) | US$ millions unless stated
B4: Fiscal year ending 31-Dec | C4: Unit | D4: Comment | E4: FY2021A | F4: FY2022A | G4: FY2023A | H4: FY2024A | I4: FY2025A | J4: FY2026E | K4: FY2027E | L4: FY2028E | M4: FY2029E | N4: FY2030E | O4: FY2031E | P4: FY2032E | Q4: FY2033E | R4: FY2034E | S4: FY2035E
B6: Model controls & market data
B7: Scenario (1 = Base, 2 = Bull, 3 = Bear) | D7: Drives every CHOOSE() on this sheet | E7: 1
B8: Circularity switch (1 = average balances, 0 = opening) | D8: Set to 0 if Excel ever shows a circular-reference warning, then back to 1 | E8: 1
B9: Share price (US$) - Nasdaq close 30-Sep-2026 (valuation date) | D9: Nasdaq close; update before use | E9: 118.54
B10: Basic shares outstanding (m) - 23-Jul-2026 | D10: 10-Q Q2-26 cover page | E10: 47.945
B11: Return all excess cash once revolver & TLB are repaid (1 = yes) | D11: Stops idle cash piling up; mgmt targets 1.0-1.5x leverage | E11: 1
B12: Buyback price method (1 = constant P/E on trailing EPS, 2 = fixed growth) | D12: Mode 1 keeps the multiple constant, so cheap buybacks do not compound forever | E12: 1
B13: Repurchase price growth p.a. (mode 2 only) | D13: ~cost of equity | E13: 0.08
B14: Minimum operating cash balance | D14: FY25 year-end 130; LTM 170 | E14: 150
B15: Interest rate earned on cash | E15: 0.03
B16: Revolving credit facility capacity | D16: 10-K: $1.0bn senior revolver | E16: 1000
B17: Revolver margin over SOFR | D17: 10-K grid: SOFR + 1.35% to 1.98% | E17: 0.015
B18: Commitment fee on undrawn revolver | E18: 0.002
B19: Term Loan B margin over SOFR | D19: 10-K: SOFR + 2.25%; matures Feb-2029 | E19: 0.0225
B20: Excess-cash sweep to Term Loan B | D20: After the revolver is repaid | E20: 1
B21: Coupon - 4.25% senior notes due Mar-2029 | D21: 10-K; $350m outstanding | E21: 0.0425
B22: Coupon - 4.125% senior notes due Aug-2031 | D22: 10-K; $350m outstanding | E22: 0.04125
B23: Refinance senior notes at maturity (1 = yes) | D23: 0 = repay from cash / revolver | E23: 1
B24: Coupon on refinancing notes | D24: Assumption: BB-rated consumer credit | E24: 0.0575
B25: Amortisation of deferred financing fees p.a. | D25: Unamortised $31.1m at FY25 | E25: 9
B26: Shares issued on RSU vesting p.a. (m) | D26: Net of withholding | E26: 0.4
B27: Dilutive securities (m) | D27: FY25: 0.37m under treasury-stock method | E27: 0.4
B28: Live scenario used by the model | D28: Equals the selector unless the Dashboard scenario table is overriding it | E28: =IF(ScenarioOverride=0,Scenario_Select,ScenarioOverride) -> 1
B29: Revenue drivers (scenario)
B30: Crocs North America wholesale growth | D30: H1-26 -14%; retailers de-stocking the clog, DTC taking share | F30: =IFERROR(Rev_Build!F7/Rev_Build!E7-1,"n.m.") -> -0.04451745 | G30: =IFERROR(Rev_Build!G7/Rev_Build!F7-1,"n.m.") -> 0.013548272 | H30: =IFERROR(Rev_Build!H7/Rev_Build!G7-1,"n.m.") -> -0.012913838 | I30: =IFERROR(Rev_Build!I7/Rev_Build!H7-1,"n.m.") -> -0.092836274 | J30: =CHOOSE(Scenario,J31,J32,J33)+GrowthShift -> -0.1 | K30: =CHOOSE(Scenario,K31,K32,K33)+GrowthShift -> -0.03 | L30: =CHOOSE(Scenario,L31,L32,L33)+GrowthShift -> 0 | M30: =CHOOSE(Scenario,M31,M32,M33)+GrowthShift -> 0.01 | N30: =CHOOSE(Scenario,N31,N32,N33)+GrowthShift -> 0.02 | O30: =CHOOSE(Scenario,O31,O32,O33)+GrowthShift -> 0.021 | P30: =CHOOSE(Scenario,P31,P32,P33)+GrowthShift -> 0.022 | Q30: =CHOOSE(Scenario,Q31,Q32,Q33)+GrowthShift -> 0.023 | ... S30: =CHOOSE(Scenario,S31,S32,S33)+GrowthShift -> 0.025
B31: Base | J31: -0.1 | K31: -0.03 | L31: 0 | M31: 0.01 | N31: 0.02 | O31: 0.021 | P31: 0.022 | Q31: 0.023 | R31: 0.024 | S31: 0.025
B32: Bull | J32: -0.08 | K32: 0.01 | L32: 0.03 | M32: 0.03 | N32: 0.03 | O32: 0.03 | P32: 0.03 | Q32: 0.03 | R32: 0.03 | S32: 0.03
B33: Bear | J33: -0.12 | K33: -0.08 | L33: -0.05 | M33: -0.03 | N33: -0.02 | O33: -0.014 | P33: -0.008 | Q33: -0.002 | R33: 0.004 | S33: 0.01
B34: Crocs North America DTC growth | D34: H1-26 +5%; mature channel, growth ~ nominal consumer spend | F34: =IFERROR(Rev_Build!F9/Rev_Build!E9-1,"n.m.") -> 0.13719042 | G34: =IFERROR(Rev_Build!G9/Rev_Build!F9-1,"n.m.") -> 0.12444612 | H34: =IFERROR(Rev_Build!H9/Rev_Build!G9-1,"n.m.") -> 0.056864265 | I34: =IFERROR(Rev_Build!I9/Rev_Build!H9-1,"n.m.") -> -0.053791243 | J34: =CHOOSE(Scenario,J35,J36,J37)+GrowthShift -> 0.03 | K34: =CHOOSE(Scenario,K35,K36,K37)+GrowthShift -> 0.03 | L34: =CHOOSE(Scenario,L35,L36,L37)+GrowthShift -> 0.03 | M34: =CHOOSE(Scenario,M35,M36,M37)+GrowthShift -> 0.03 | N34: =CHOOSE(Scenario,N35,N36,N37)+GrowthShift -> 0.03 | O34: =CHOOSE(Scenario,O35,O36,O37)+GrowthShift -> 0.029 | P34: =CHOOSE(Scenario,P35,P36,P37)+GrowthShift -> 0.028 | Q34: =CHOOSE(Scenario,Q35,Q36,Q37)+GrowthShift -> 0.027 | ... S34: =CHOOSE(Scenario,S35,S36,S37)+GrowthShift -> 0.025
B35: Base | J35: 0.03 | K35: 0.03 | L35: 0.03 | M35: 0.03 | N35: 0.03 | O35: 0.029 | P35: 0.028 | Q35: 0.027 | R35: 0.026 | S35: 0.025
B36: Bull | J36: 0.05 | K36: 0.05 | L36: 0.04 | M36: 0.04 | N36: 0.04 | O36: 0.038 | P36: 0.036 | Q36: 0.034 | R36: 0.032 | S36: 0.03
B37: Bear | J37: 0.01 | K37: -0.02 | L37: -0.02 | M37: 0 | N37: 0.01 | O37: 0.011 | P37: 0.012 | Q37: 0.013 | R37: 0.014 | S37: 0.015
B38: Crocs International wholesale growth | D38: H1-26 -1% as distributor markets move to DTC (takebacks) | F38: =IFERROR(Rev_Build!F11/Rev_Build!E11-1,"n.m.") -> 0.46661105 | G38: =IFERROR(Rev_Build!G11/Rev_Build!F11-1,"n.m.") -> 0.14664972 | H38: =IFERROR(Rev_Build!H11/Rev_Build!G11-1,"n.m.") -> 0.14566009 | I38: =IFERROR(Rev_Build!I11/Rev_Build!H11-1,"n.m.") -> 0.053644987 | J38: =CHOOSE(Scenario,J39,J40,J41)+GrowthShift -> 0 | K38: =CHOOSE(Scenario,K39,K40,K41)+GrowthShift -> 0.04 | L38: =CHOOSE(Scenario,L39,L40,L41)+GrowthShift -> 0.05 | M38: =CHOOSE(Scenario,M39,M40,M41)+GrowthShift -> 0.05 | N38: =CHOOSE(Scenario,N39,N40,N41)+GrowthShift -> 0.04 | O38: =CHOOSE(Scenario,O39,O40,O41)+GrowthShift -> 0.038 | P38: =CHOOSE(Scenario,P39,P40,P41)+GrowthShift -> 0.036 | Q38: =CHOOSE(Scenario,Q39,Q40,Q41)+GrowthShift -> 0.034 | ... S38: =CHOOSE(Scenario,S39,S40,S41)+GrowthShift -> 0.03
B39: Base | J39: 0 | K39: 0.04 | L39: 0.05 | M39: 0.05 | N39: 0.04 | O39: 0.038 | P39: 0.036 | Q39: 0.034 | R39: 0.032 | S39: 0.03
B40: Bull | J40: 0.02 | K40: 0.07 | L40: 0.07 | M40: 0.06 | N40: 0.05 | O40: 0.047 | P40: 0.044 | Q40: 0.041 | R40: 0.038 | S40: 0.035
B41: Bear | J41: -0.03 | K41: -0.02 | L41: 0.01 | M41: 0.02 | N41: 0.02 | O41: 0.02 | P41: 0.02 | Q41: 0.02 | R41: 0.02 | S41: 0.02
B42: Crocs International DTC growth | D42: H1-26 +26%; China, India, SE Asia store & e-com build-out | F42: =IFERROR(Rev_Build!F13/Rev_Build!E13-1,"n.m.") -> 0.083960291 | G42: =IFERROR(Rev_Build!G13/Rev_Build!F13-1,"n.m.") -> 0.40191981 | H42: =IFERROR(Rev_Build!H13/Rev_Build!G13-1,"n.m.") -> 0.22063502 | I42: =IFERROR(Rev_Build!I13/Rev_Build!H13-1,"n.m.") -> 0.24914332 | J42: =CHOOSE(Scenario,J43,J44,J45)+GrowthShift -> 0.18 | K42: =CHOOSE(Scenario,K43,K44,K45)+GrowthShift -> 0.12 | L42: =CHOOSE(Scenario,L43,L44,L45)+GrowthShift -> 0.1 | M42: =CHOOSE(Scenario,M43,M44,M45)+GrowthShift -> 0.08 | N42: =CHOOSE(Scenario,N43,N44,N45)+GrowthShift -> 0.07 | O42: =CHOOSE(Scenario,O43,O44,O45)+GrowthShift -> 0.063 | P42: =CHOOSE(Scenario,P43,P44,P45)+GrowthShift -> 0.056 | Q42: =CHOOSE(Scenario,Q43,Q44,Q45)+GrowthShift -> 0.049 | ... S42: =CHOOSE(Scenario,S43,S44,S45)+GrowthShift -> 0.035
...

Sheet Rev_Build
B1: Revenue build - brand x region x channel
B2: Crocs, Inc. (NASDAQ: CROX) | US$ millions unless stated
B4: Fiscal year ending 31-Dec | C4: Unit | E4: FY2021A | F4: FY2022A | G4: FY2023A | H4: FY2024A | I4: FY2025A | J4: FY2026E | K4: FY2027E | L4: FY2028E | M4: FY2029E | N4: FY2030E | O4: FY2031E | P4: FY2032E | Q4: FY2033E | R4: FY2034E | S4: FY2035E
B6: Crocs brand
B7: North America - Wholesale | E7: =Hist!E83 -> 674.23 | F7: =Hist!F83 -> 644.215 | G7: =Hist!G83 -> 652.943 | H7: =Hist!H83 -> 644.511 | I7: =Hist!I83 -> 584.677 | J7: =I7*(1+Inputs!J30) -> 526.2093 | K7: =J7*(1+Inputs!K30) -> 510.42302 | L7: =K7*(1+Inputs!L30) -> 510.42302 | M7: =L7*(1+Inputs!M30) -> 515.52725 | N7: =M7*(1+Inputs!N30) -> 525.8378 | O7: =N7*(1+Inputs!O30) -> 536.88039 | P7: =O7*(1+Inputs!P30) -> 548.69176 | Q7: =P7*(1+Inputs!Q30) -> 561.31167 | ... S7: =R7*(1+Inputs!S30) -> 589.15273
B8: growth | F8: =IFERROR(F7/E7-1,"n.m.") -> -0.04451745 | G8: =IFERROR(G7/F7-1,"n.m.") -> 0.013548272 | H8: =IFERROR(H7/G7-1,"n.m.") -> -0.012913838 | I8: =IFERROR(I7/H7-1,"n.m.") -> -0.092836274 | J8: =Inputs!J30 -> -0.1 | K8: =Inputs!K30 -> -0.03 | L8: =Inputs!L30 -> 0 | M8: =Inputs!M30 -> 0.01 | N8: =Inputs!N30 -> 0.02 | O8: =Inputs!O30 -> 0.021 | P8: =Inputs!P30 -> 0.022 | Q8: =Inputs!Q30 -> 0.023 | ... S8: =Inputs!S30 -> 0.025
B9: North America - DTC | E9: =Hist!E84 -> 879.748 | F9: =Hist!F84 -> 1000.441 | G9: =Hist!G84 -> 1124.942 | H9: =Hist!H84 -> 1188.911 | I9: =Hist!I84 -> 1124.958 | J9: =I9*(1+Inputs!J34) -> 1158.7067 | K9: =J9*(1+Inputs!K34) -> 1193.4679 | L9: =K9*(1+Inputs!L34) -> 1229.272 | M9: =L9*(1+Inputs!M34) -> 1266.1501 | N9: =M9*(1+Inputs!N34) -> 1304.1346 | O9: =N9*(1+Inputs!O34) -> 1341.9545 | P9: =O9*(1+Inputs!P34) -> 1379.5293 | Q9: =P9*(1+Inputs!Q34) -> 1416.7766 | ... S9: =R9*(1+Inputs!S34) -> 1489.9531
B10: growth | F10: =IFERROR(F9/E9-1,"n.m.") -> 0.13719042 | G10: =IFERROR(G9/F9-1,"n.m.") -> 0.12444612 | H10: =IFERROR(H9/G9-1,"n.m.") -> 0.056864265 | I10: =IFERROR(I9/H9-1,"n.m.") -> -0.053791243 | J10: =Inputs!J34 -> 0.03 | K10: =Inputs!K34 -> 0.03 | L10: =Inputs!L34 -> 0.03 | M10: =Inputs!M34 -> 0.03 | N10: =Inputs!N34 -> 0.03 | O10: =Inputs!O34 -> 0.029 | P10: =Inputs!P34 -> 0.028 | Q10: =Inputs!Q34 -> 0.027 | ... S10: =Inputs!S34 -> 0.025
B11: International - Wholesale | E11: =Hist!E85 -> 499.851 | F11: =Hist!F85 -> 733.087 | G11: =Hist!G85 -> 840.594 | H11: =Hist!H85 -> 963.035 | I11: =Hist!I85 -> 1014.697 | J11: =I11*(1+Inputs!J38) -> 1014.697 | K11: =J11*(1+Inputs!K38) -> 1055.2849 | L11: =K11*(1+Inputs!L38) -> 1108.0491 | M11: =L11*(1+Inputs!M38) -> 1163.4516 | N11: =M11*(1+Inputs!N38) -> 1209.9896 | O11: =N11*(1+Inputs!O38) -> 1255.9692 | P11: =O11*(1+Inputs!P38) -> 1301.1841 | Q11: =P11*(1+Inputs!Q38) -> 1345.4244 | ... S11: =R11*(1+Inputs!S38) -> 1430.1323
B12: growth | F12: =IFERROR(F11/E11-1,"n.m.") -> 0.46661105 | G12: =IFERROR(G11/F11-1,"n.m.") -> 0.14664972 | H12: =IFERROR(H11/G11-1,"n.m.") -> 0.14566009 | I12: =IFERROR(I11/H11-1,"n.m.") -> 0.053644987 | J12: =Inputs!J38 -> 0 | K12: =Inputs!K38 -> 0.04 | L12: =Inputs!L38 -> 0.05 | M12: =Inputs!M38 -> 0.05 | N12: =Inputs!N38 -> 0.04 | O12: =Inputs!O38 -> 0.038 | P12: =Inputs!P38 -> 0.036 | Q12: =Inputs!Q38 -> 0.034 | ... S12: =Inputs!S38 -> 0.03
B13: International - DTC | E13: =Hist!E86 -> 259.587 | F13: =Hist!F86 -> 281.382 | G13: =Hist!G86 -> 394.475 | H13: =Hist!H86 -> 481.51 | I13: =Hist!I86 -> 601.475 | J13: =I13*(1+Inputs!J42) -> 709.7405 | K13: =J13*(1+Inputs!K42) -> 794.90936 | L13: =K13*(1+Inputs!L42) -> 874.4003 | M13: =L13*(1+Inputs!M42) -> 944.35232 | N13: =M13*(1+Inputs!N42) -> 1010.457 | O13: =N13*(1+Inputs!O42) -> 1074.1158 | P13: =O13*(1+Inputs!P42) -> 1134.2663 | Q13: =P13*(1+Inputs!Q42) -> 1189.8453 | ... S13: =R13*(1+Inputs!S42) -> 1283.2125
B14: growth | F14: =IFERROR(F13/E13-1,"n.m.") -> 0.083960291 | G14: =IFERROR(G13/F13-1,"n.m.") -> 0.40191981 | H14: =IFERROR(H13/G13-1,"n.m.") -> 0.22063502 | I14: =IFERROR(I13/H13-1,"n.m.") -> 0.24914332 | J14: =Inputs!J42 -> 0.18 | K14: =Inputs!K42 -> 0.12 | L14: =Inputs!L42 -> 0.1 | M14: =Inputs!M42 -> 0.08 | N14: =Inputs!N42 -> 0.07 | O14: =Inputs!O42 -> 0.063 | P14: =Inputs!P42 -> 0.056 | Q14: =Inputs!Q42 -> 0.049 | ... S14: =Inputs!S42 -> 0.035
B15: Crocs North America | E15: =E7+E9 -> 1553.978 | F15: =F7+F9 -> 1644.656 | G15: =G7+G9 -> 1777.885 | H15: =H7+H9 -> 1833.422 | I15: =I7+I9 -> 1709.635 | J15: =J7+J9 -> 1684.916 | K15: =K7+K9 -> 1703.891 | L15: =L7+L9 -> 1739.695 | ... S15: =S7+S9 -> 2079.1058
B16: Crocs International | E16: =E11+E13 -> 759.438 | F16: =F11+F13 -> 1014.469 | G16: =G11+G13 -> 1235.069 | H16: =H11+H13 -> 1444.545 | I16: =I11+I13 -> 1616.172 | J16: =J11+J13 -> 1724.4375 | K16: =K11+K13 -> 1850.1942 | L16: =L11+L13 -> 1982.4494 | ... S16: =S11+S13 -> 2713.3448
B17: Crocs brand revenue | E17: =E15+E16 -> 2313.416 | F17: =F15+F16 -> 2659.125 | G17: =G15+G16 -> 3012.954 | H17: =H15+H16 -> 3277.967 | I17: =I15+I16 -> 3325.807 | J17: =J15+J16 -> 3409.3535 | K17: =K15+K16 -> 3554.0852 | L17: =L15+L16 -> 3722.1444 | ... S17: =S15+S16 -> 4792.4506
B18: growth | F18: =IFERROR(F17/E17-1,"n.m.") -> 0.14943659 | G18: =IFERROR(G17/F17-1,"n.m.") -> 0.13306219 | H18: =IFERROR(H17/G17-1,"n.m.") -> 0.087957865 | I18: =IFERROR(I17/H17-1,"n.m.") -> 0.014594412 | J18: =J17/I17-1 -> 0.025120682 | K18: =K17/J17-1 -> 0.042451351 | L18: =L17/K17-1 -> 0.04728621 | M18: =M17/L17-1 -> 0.044957114 | N18: =N17/M17-1 -> 0.041377696 | O18: =O17/N17-1 -> 0.039131974 | P18: =P17/O17-1 -> 0.036767502 | Q18: =Q17/P17-1 -> 0.034302882 | ... S18: =S17/R17-1 -> 0.029153286
B19: HEYDUDE brand
B20: Wholesale | E20: =Hist!E87 -> 0 | F20: =Hist!F87 -> 574.14 | G20: =Hist!G87 -> 566.937 | H20: =Hist!H87 -> 456.472 | I20: =Hist!I87 -> 336.325 | J20: =I20*(1+Inputs!J46) -> 285.87625 | K20: =J20*(1+Inputs!K46) -> 268.72367 | L20: =K20*(1+Inputs!L46) -> 263.3492 | M20: =L20*(1+Inputs!M46) -> 265.98269 | N20: =M20*(1+Inputs!N46) -> 271.30235 | O20: =N20*(1+Inputs!O46) -> 276.9997 | P20: =O20*(1+Inputs!P46) -> 283.09369 | Q20: =P20*(1+Inputs!Q46) -> 289.60484 | ... S20: =R20*(1+Inputs!S46) -> 303.96925
B21: growth | F21: =IFERROR(F20/E20-1,"n.m.") -> n.m. | G21: =IFERROR(G20/F20-1,"n.m.") -> -0.012545721 | H21: =IFERROR(H20/G20-1,"n.m.") -> -0.19484528 | I21: =IFERROR(I20/H20-1,"n.m.") -> -0.26320782 | J21: =Inputs!J46 -> -0.15 | K21: =Inputs!K46 -> -0.06 | L21: =Inputs!L46 -> -0.02 | M21: =Inputs!M46 -> 0.01 | N21: =Inputs!N46 -> 0.02 | O21: =Inputs!O46 -> 0.021 | P21: =Inputs!P46 -> 0.022 | Q21: =Inputs!Q46 -> 0.023 | ... S21: =Inputs!S46 -> 0.025
B22: DTC | E22: =Hist!E88 -> 0 | F22: =Hist!F88 -> 321.72 | G22: =Hist!G88 -> 382.456 | H22: =Hist!H88 -> 367.669 | I22: =Hist!I88 -> 378.515 | J22: =I22*(1+Inputs!J50) -> 408.7962 | K22: =J22*(1+Inputs!K50) -> 425.14805 | L22: =K22*(1+Inputs!L50) -> 437.90249 | M22: =L22*(1+Inputs!M50) -> 450.7269 | N22: =M22*(1+Inputs!N50) -> 463.60462 | O22: =N22*(1+Inputs!O50) -> 476.51925 | P22: =O22*(1+Inputs!P50) -> 489.45342 | Q22: =P22*(1+Inputs!Q50) -> 502.38918 | ... S22: =R22*(1+Inputs!S50) -> 528.19031
B23: growth | F23: =IFERROR(F22/E22-1,"n.m.") -> n.m. | G23: =IFERROR(G22/F22-1,"n.m.") -> 0.18878528 | H23: =IFERROR(H22/G22-1,"n.m.") -> -0.038663271 | I23: =IFERROR(I22/H22-1,"n.m.") -> 0.029499359 | J23: =Inputs!J50 -> 0.08 | K23: =Inputs!K50 -> 0.04 | L23: =Inputs!L50 -> 0.03 | M23: =Inputs!M50 -> 0.029286 | N23: =Inputs!N50 -> 0.028571 | O23: =Inputs!O50 -> 0.027857 | P23: =Inputs!P50 -> 0.027143 | Q23: =Inputs!Q50 -> 0.026429 | ... S23: =Inputs!S50 -> 0.025
B24: HEYDUDE revenue | E24: =E20+E22 -> 0 | F24: =F20+F22 -> 895.86 | G24: =G20+G22 -> 949.393 | H24: =H20+H22 -> 824.141 | I24: =I20+I22 -> 714.84 | J24: =J20+J22 -> 694.67245 | K24: =K20+K22 -> 693.87172 | L24: =L20+L22 -> 701.25169 | ... S24: =S20+S22 -> 832.15955
B25: growth | G25: =IFERROR(G24/F24-1,"n.m.") -> 0.059755989 | H25: =IFERROR(H24/G24-1,"n.m.") -> -0.13192851 | I25: =IFERROR(I24/H24-1,"n.m.") -> -0.13262415 | J25: =J24/I24-1 -> -0.028212677 | K25: =K24/J24-1 -> -0.0011526684 | L25: =L24/K24-1 -> 0.010635925 | M25: =M24/L24-1 -> 0.022043304 | N25: =N24/M24-1 -> 0.025390161 | O25: =O24/N24-1 -> 0.025325632 | P25: =P24/O24-1 -> 0.025252391 | Q25: =Q24/P24-1 -> 0.02517247 | ... S25: =S24/R24-1 -> 0.025
B26: Consolidated
B27: Total revenue | E27: =E17+E24 -> 2313.416 | F27: =F17+F24 -> 3554.985 | G27: =G17+G24 -> 3962.347 | H27: =H17+H24 -> 4102.108 | I27: =I17+I24 -> 4040.647 | J27: =J17+J24 -> 4104.026 | K27: =K17+K24 -> 4247.9569 | L27: =L17+L24 -> 4423.3961 | ... S27: =S17+S24 -> 5624.6101
B28: growth | F28: =IFERROR(F27/E27-1,"n.m.") -> 0.53668212 | G28: =IFERROR(G27/F27-1,"n.m.") -> 0.11458895 | H28: =IFERROR(H27/G27-1,"n.m.") -> 0.035272277 | I28: =IFERROR(I27/H27-1,"n.m.") -> -0.014982784 | J28: =J27/I27-1 -> 0.015685357 | K28: =K27/J27-1 -> 0.035070669 | L28: =L27/K27-1 -> 0.041299662 | M28: =M27/L27-1 -> 0.041324532 | N28: =N27/M27-1 -> 0.038890083 | O28: =O27/N27-1 -> 0.037011664 | P28: =P27/O27-1 -> 0.035018996 | Q28: =Q27/P27-1 -> 0.032929562 | ... S28: =S27/R27-1 -> 0.028536689
B29: Direct-to-consumer revenue | E29: =E9+E13+E22 -> 1139.335 | F29: =F9+F13+F22 -> 1603.543 | G29: =G9+G13+G22 -> 1901.873 | H29: =H9+H13+H22 -> 2038.09 | I29: =I9+I13+I22 -> 2104.948 | J29: =J9+J13+J22 -> 2277.2434 | K29: =K9+K13+K22 -> 2413.5254 | L29: =L9+L13+L22 -> 2541.5748 | ... S29: =S9+S13+S22 -> 3301.3558
B30: DTC share of revenue | E30: =E29/E27 -> 0.49249033 | F30: =F29/F27 -> 0.45106885 | G30: =G29/G27 -> 0.47998648 | H30: =H29/H27 -> 0.49683967 | I30: =I29/I27 -> 0.5209433 | J30: =J29/J27 -> 0.55488037 | K30: =K29/K27 -> 0.56816145 | L30: =L29/L27 -> 0.57457544 | ... S30: =S29/S27 -> 0.58694839
B31: Crocs International share of Crocs brand | E31: =E16/E17 -> 0.32827559 | F31: =F16/F17 -> 0.38150482 | G31: =G16/G17 -> 0.40991963 | H31: =H16/H17 -> 0.4406832 | I31: =I16/I17 -> 0.48594882 | J31: =J16/J17 -> 0.50579603 | K31: =K16/K17 -> 0.52058241 | L31: =L16/L17 -> 0.53260948 | ... S31: =S16/S17 -> 0.56617063
B32: HEYDUDE share of revenue | E32: =E24/E27 -> 0 | F32: =F24/F27 -> 0.25200106 | G32: =G24/G27 -> 0.2396037 | H32: =H24/H27 -> 0.2009067 | I32: =I24/I27 -> 0.17691226 | J32: =J24/J27 -> 0.16926609 | K32: =K24/K27 -> 0.16334246 | L32: =L24/L27 -> 0.15853242 | ... S32: =S24/S27 -> 0.14794973
B33: Cross-check: units x ASP (footwear only)
B34: Crocs footwear ASP (US$) | E34: =Hist!E101 -> 22.27 | F34: =Hist!F101 -> 22.72 | G34: =Hist!G101 -> 24.92 | H34: =Hist!H101 -> 25.52 | I34: =Hist!I101 -> 25.4 | J34: =I34*(1+Inputs!J107) -> 25.908 | K34: =J34*(1+Inputs!K107) -> 26.42616 | L34: =K34*(1+Inputs!L107) -> 26.954683 | M34: =L34*(1+Inputs!M107) -> 27.493777 | N34: =M34*(1+Inputs!N107) -> 28.043652 | O34: =N34*(1+Inputs!O107) -> 28.604525 | P34: =O34*(1+Inputs!P107) -> 29.176616 | Q34: =P34*(1+Inputs!Q107) -> 29.760148 | ... S34: =R34*(1+Inputs!S107) -> 30.962458
B35: Crocs footwear share of brand revenue | E35: =Hist!E100*Hist!E101/E17 -> 0.99115928 | F35: =Hist!F100*Hist!F101/F17 -> 0.9873465 | G35: =Hist!G100*Hist!G101/G17 -> 0.98901571 | H35: =Hist!H100*Hist!H101/H17 -> 0.98873479 | I35: =Hist!I100*Hist!I101/I17 -> 0.98473098 | J35: =$I$35 -> 0.98473098 | K35: =$I$35 -> 0.98473098 | L35: =$I$35 -> 0.98473098 | M35: =$I$35 -> 0.98473098 | N35: =$I$35 -> 0.98473098 | O35: =$I$35 -> 0.98473098 | P35: =$I$35 -> 0.98473098 | Q35: =$I$35 -> 0.98473098 | ... S35: =$I$35 -> 0.98473098
B36: Crocs implied footwear units (m pairs) | E36: =Hist!E100 -> 102.962 | F36: =Hist!F100 -> 115.558 | G36: =Hist!G100 -> 119.577 | H36: =Hist!H100 -> 127 | I36: =Hist!I100 -> 128.938 | J36: =J17*J35/J34 -> 129.5853 | K36: =K17*K35/K34 -> 132.43762 | L36: =L17*L35/L34 -> 135.98049 | M36: =M17*M35/M34 -> 139.30762 | N36: =N17*N35/N34 -> 142.22731 | O36: =O17*O35/O34 -> 144.89504 | P36: =P17*P35/P34 -> 147.27693 | Q36: =Q17*Q35/Q34 -> 149.34211 | ... S36: =S17*S35/S34 -> 152.41925
B37: implied unit growth | F37: =IFERROR(F36/E36-1,"n.m.") -> 0.1223364 | G37: =IFERROR(G36/F36-1,"n.m.") -> 0.034779072 | H37: =IFERROR(H36/G36-1,"n.m.") -> 0.062077155 | I37: =IFERROR(I36/H36-1,"n.m.") -> 0.015259843 | J37: =J36/I36-1 -> 0.0050202765 | K37: =K36/J36-1 -> 0.022011128 | L37: =L36/K36-1 -> 0.026751186 | M37: =M36/L36-1 -> 0.024467758 | N37: =N36/M36-1 -> 0.020958526 | O37: =O36/N36-1 -> 0.018756838 | P37: =P36/O36-1 -> 0.016438727 | Q37: =Q36/P36-1 -> 0.014022434 | ... S37: =S36/R36-1 -> 0.0089738101
B38: HEYDUDE footwear ASP (US$) | F38: =Hist!F103 -> 29.35 | G38: =Hist!G103 -> 28.8 | H38: =Hist!H103 -> 30.54 | I38: =Hist!I103 -> 31.67 | J38: =I38*(1+Inputs!J108) -> 31.9867 | K38: =J38*(1+Inputs!K108) -> 32.306567 | L38: =K38*(1+Inputs!L108) -> 32.629633 | M38: =L38*(1+Inputs!M108) -> 32.955929 | N38: =M38*(1+Inputs!N108) -> 33.285488 | O38: =N38*(1+Inputs!O108) -> 33.618343 | P38: =O38*(1+Inputs!P108) -> 33.954527 | Q38: =P38*(1+Inputs!Q108) -> 34.294072 | ... S38: =R38*(1+Inputs!S108) -> 34.983383
B39: HEYDUDE footwear share of brand revenue | F39: =Hist!F102*Hist!F103/F24 -> 0.99985785 | G39: =Hist!G102*Hist!G103/G24 -> 1.0001203 | H39: =Hist!H102*Hist!H103/H24 -> 0.99867984 | I39: =Hist!I102*Hist!I103/I24 -> 0.9949264 | J39: =$I$39 -> 0.9949264 | K39: =$I$39 -> 0.9949264 | L39: =$I$39 -> 0.9949264 | M39: =$I$39 -> 0.9949264 | N39: =$I$39 -> 0.9949264 | O39: =$I$39 -> 0.9949264 | P39: =$I$39 -> 0.9949264 | Q39: =$I$39 -> 0.9949264 | ... S39: =$I$39 -> 0.9949264
B40: HEYDUDE implied footwear units (m pairs) | F40: =Hist!F102 -> 30.519 | G40: =Hist!G102 -> 32.969 | H40: =Hist!H102 -> 26.95 | I40: =Hist!I102 -> 22.457 | J40: =J24*J39/J38 -> 21.607354 | K40: =K24*K39/K38 -> 21.368761 | L40: =L24*L39/L38 -> 21.382215 | M40: =M24*M39/M38 -> 21.637178 | N40: =N24*N39/N38 -> 21.966881 | O40: =O24*O39/O38 -> 22.300204 | P40: =P24*P39/P38 -> 22.636967 | Q40: =Q24*Q39/Q38 -> 22.977026 | ... S40: =S24*S39/S38 -> 23.666594
B41: implied unit growth | G41: =IFERROR(G40/F40-1,"n.m.") -> 0.08027786 | H41: =IFERROR(H40/G40-1,"n.m.") -> -0.18256544 | I41: =IFERROR(I40/H40-1,"n.m.") -> -0.16671614 | J41: =J40/I40-1 -> -0.037834334 | K41: =K40/J40-1 -> -0.011042246 | L41: =L40/K40-1 -> 0.00062962919 | M41: =M40/L40-1 -> 0.011924064 | N41: =N40/M40-1 -> 0.015237783 | O41: =O40/N40-1 -> 0.015173893 | P41: =P40/O40-1 -> 0.015101378 | Q41: =Q40/P40-1 -> 0.015022248 | ... S41: =S40/R40-1 -> 0.014851485

Sheet IS
B1: Income statement
B2: Crocs, Inc. (NASDAQ: CROX) | US$ millions unless stated
B4: Fiscal year ending 31-Dec | C4: Unit | E4: FY2021A | F4: FY2022A | G4: FY2023A | H4: FY2024A | I4: FY2025A | J4: FY2026E | K4: FY2027E | L4: FY2028E | M4: FY2029E | N4: FY2030E | O4: FY2031E | P4: FY2032E | Q4: FY2033E | R4: FY2034E | S4: FY2035E
B6: Profit & loss
B7: Revenue | E7: =Rev_Build!E27 -> 2313.416 | F7: =Rev_Build!F27 -> 3554.985 | G7: =Rev_Build!G27 -> 3962.347 | H7: =Rev_Build!H27 -> 4102.108 | I7: =Rev_Build!I27 -> 4040.647 | J7: =Rev_Build!J27 -> 4104.026 | K7: =Rev_Build!K27 -> 4247.9569 | L7: =Rev_Build!L27 -> 4423.3961 | ... S7: =Rev_Build!S27 -> 5624.6101
B8: growth | F8: =IFERROR(F7/E7-1,"n.m.") -> 0.53668212 | G8: =IFERROR(G7/F7-1,"n.m.") -> 0.11458895 | H8: =IFERROR(H7/G7-1,"n.m.") -> 0.035272277 | I8: =IFERROR(I7/H7-1,"n.m.") -> -0.014982784 | J8: =J7/I7-1 -> 0.015685357 | K8: =K7/J7-1 -> 0.035070669 | L8: =L7/K7-1 -> 0.041299662 | M8: =M7/L7-1 -> 0.041324532 | N8: =N7/M7-1 -> 0.038890083 | O8: =O7/N7-1 -> 0.037011664 | P8: =P7/O7-1 -> 0.035018996 | Q8: =Q7/P7-1 -> 0.032929562 | ... S8: =S7/R7-1 -> 0.028536689
B9: Cost of sales | E9: =Hist!E8 -> 893.196 | F9: =Hist!F8 -> 1694.703 | G9: =Hist!G8 -> 1752.337 | H9: =Hist!H8 -> 1691.85 | I9: =Hist!I8 -> 1683.592 | J9: =Rev_Build!J17*(1-Inputs!J55)+Rev_Build!J24*(1-Inputs!J59) -> 1732.5579 | K9: =Rev_Build!K17*(1-Inputs!K55)+Rev_Build!K24*(1-Inputs!K59) -> 1781.6001 | L9: =Rev_Build!L17*(1-Inputs!L55)+Rev_Build!L24*(1-Inputs!L59) -> 1844.3373 | M9: =Rev_Build!M17*(1-Inputs!M55)+Rev_Build!M24*(1-Inputs!M59) -> 1918.2551 | N9: =Rev_Build!N17*(1-Inputs!N55)+Rev_Build!N24*(1-Inputs!N59) -> 1991.2113 | O9: =Rev_Build!O17*(1-Inputs!O55)+Rev_Build!O24*(1-Inputs!O59) -> 2063.4494 | P9: =Rev_Build!P17*(1-Inputs!P55)+Rev_Build!P24*(1-Inputs!P59) -> 2134.4582 | Q9: =Rev_Build!Q17*(1-Inputs!Q55)+Rev_Build!Q24*(1-Inputs!Q59) -> 2203.7263 | ... S9: =Rev_Build!S17*(1-Inputs!S55)+Rev_Build!S24*(1-Inputs!S59) -> 2335.0651
B10: Gross profit | E10: =E7-E9 -> 1420.22 | F10: =F7-F9 -> 1860.282 | G10: =G7-G9 -> 2210.01 | H10: =H7-H9 -> 2410.258 | I10: =I7-I9 -> 2357.055 | J10: =J7-J9 -> 2371.4681 | K10: =K7-K9 -> 2466.3568 | L10: =L7-L9 -> 2579.0588 | ... S10: =S7-S9 -> 3289.5451
B11: gross margin | E11: =E10/E7 -> 0.61390602 | F11: =F10/F7 -> 0.52328828 | G11: =G10/G7 -> 0.55775277 | H11: =H10/H7 -> 0.58756571 | I11: =I10/I7 -> 0.58333604 | J11: =J10/J7 -> 0.57783944 | K11: =K10/K7 -> 0.58059836 | L11: =L10/L7 -> 0.58304949 | ... S11: =S10/S7 -> 0.58484855
B12: SG&A (incl. restructuring charges) | E12: =Hist!E10 -> 737.156 | F12: =Hist!F10 -> 1009.526 | G12: =Hist!G10 -> 1163.94 | H12: =Hist!H10 -> 1364.265 | I12: =Hist!I10 -> 1469.425 | J12: =J27+J28+J29+J30 -> 1478.7201 | K12: =K27+K28+K29+K30 -> 1512.7879 | L12: =L27+L28+L29+L30 -> 1566.0162 | M12: =M27+M28+M29+M30 -> 1621.6434 | N12: =N27+N28+N29+N30 -> 1679.223 | O12: =O27+O28+O29+O30 -> 1740.9873 | P12: =P27+P28+P29+P30 -> 1801.6238 | Q12: =Q27+Q28+Q29+Q30 -> 1860.6808 | ... S12: =S27+S28+S29+S30 -> 1972.3131
B13: % revenue | E13: =E12/E7 -> 0.31864394 | F13: =F12/F7 -> 0.28397476 | G13: =G12/G7 -> 0.29375014 | H13: =H12/H7 -> 0.33257657 | I13: =I12/I7 -> 0.36366082 | J13: =J12/J7 -> 0.36030964 | K13: =K12/K7 -> 0.3561213 | L13: =L12/L7 -> 0.35403029 | ... S13: =S12/S7 -> 0.35065774
B14: Asset impairments | E14: =Hist!E11 -> 0 | F14: =Hist!F11 -> 0 | G14: =Hist!G11 -> 9.287 | H14: =Hist!H11 -> 24.081 | I14: =Hist!I11 -> 738.115 | J14: 0 | K14: 0 | L14: 0 | M14: 0 | N14: 0 | O14: 0 | P14: 0 | Q14: 0 | R14: 0 | S14: 0
B15: Operating income (EBIT) | E15: =E10-E12-E14 -> 683.064 | F15: =F10-F12-F14 -> 850.756 | G15: =G10-G12-G14 -> 1036.783 | H15: =H10-H12-H14 -> 1021.912 | I15: =I10-I12-I14 -> 149.515 | J15: =J10-J12-J14 -> 892.74798 | K15: =K10-K12-K14 -> 953.56887 | L15: =L10-L12-L14 -> 1013.0426 | ... S15: =S10-S12-S14 -> 1317.232
B16: EBIT margin | E16: =E15/E7 -> 0.29526207 | F16: =F15/F7 -> 0.23931353 | G16: =G15/G7 -> 0.26165881 | H16: =H15/H7 -> 0.24911875 | I16: =I15/I7 -> 0.037002737 | J16: =J15/J7 -> 0.21752981 | K16: =K15/K7 -> 0.22447706 | L16: =L15/L7 -> 0.2290192 | ... S16: =S15/S7 -> 0.23419081
B17: Interest income | E17: =Hist!E13 -> 0.775 | F17: =Hist!F13 -> 1.02 | G17: =Hist!G13 -> 2.406 | H17: =Hist!H13 -> 3.484 | I17: =Hist!I13 -> 1.844 | J17: =Debt!J52 -> 4.20531 | K17: =Debt!K52 -> 4.5 | L17: =Debt!L52 -> 4.5 | M17: =Debt!M52 -> 5.5321816 | N17: =Debt!N52 -> 5.5321816 | O17: =Debt!O52 -> 4.5 | P17: =Debt!P52 -> 4.5 | Q17: =Debt!Q52 -> 4.5 | ... S17: =Debt!S52 -> 4.5
B18: Interest expense | E18: =Hist!E14 -> 21.647 | F18: =Hist!F14 -> 136.158 | G18: =Hist!G14 -> 161.351 | H18: =Hist!H14 -> 109.264 | I18: =Hist!I14 -> 88.287 | J18: =Debt!J51 -> 69.961564 | K18: =Debt!K51 -> 60.851325 | L18: =Debt!L51 -> 50.973028 | M18: =Debt!M51 -> 41.060462 | N18: =Debt!N51 -> 36.5625 | O18: =Debt!O51 -> 39.40625 | P18: =Debt!P51 -> 42.25 | Q18: =Debt!Q51 -> 42.25 | ... S18: =Debt!S51 -> 42.25
B19: Other non-operating income (incl. FX) | E19: =Hist!E15 -> 1.657 | F19: =Hist!F15 -> 2.89 | G19: =Hist!G15 -> -1.566 | H19: =Hist!H15 -> -5.546 | I19: =Hist!I15 -> 9.906 | J19: 0 | K19: 0 | L19: 0 | M19: 0 | N19: 0 | O19: 0 | P19: 0 | Q19: 0 | R19: 0 | S19: 0
B20: Pre-tax income | E20: =E15+E17-E18+E19 -> 663.849 | F20: =F15+F17-F18+F19 -> 718.508 | G20: =G15+G17-G18+G19 -> 876.272 | H20: =H15+H17-H18+H19 -> 910.586 | I20: =I15+I17-I18+I19 -> 72.978 | J20: =J15+J17-J18+J19 -> 826.99173 | K20: =K15+K17-K18+K19 -> 897.21754 | L20: =L15+L17-L18+L19 -> 966.5696 | ... S20: =S15+S17-S18+S19 -> 1279.482
B21: Income tax expense / (benefit) | E21: =Hist!E17 -> -61.845 | F21: =Hist!F17 -> 178.349 | G21: =Hist!G17 -> 83.706 | H21: =Hist!H17 -> -39.486 | I21: =Hist!I17 -> 154.176 | J21: =Tax!J8 -> 190.2081 | K21: =Tax!K8 -> 197.38786 | L21: =Tax!L8 -> 212.64531 | M21: =Tax!M8 -> 226.7681 | N21: =Tax!N8 -> 238.44951 | O21: =Tax!O8 -> 247.0811 | P21: =Tax!P8 -> 255.72503 | Q21: =Tax!Q8 -> 264.70288 | ... S21: =Tax!S8 -> 281.48604
B22: effective tax rate | E22: =IFERROR(E21/E20,"n.m.") -> -0.093161246 | F22: =IFERROR(F21/F20,"n.m.") -> 0.24822131 | G22: =IFERROR(G21/G20,"n.m.") -> 0.095525134 | H22: =IFERROR(H21/H20,"n.m.") -> -0.043363285 | I22: =IFERROR(I21/I20,"n.m.") -> 2.1126367 | J22: =J21/J20 -> 0.23 | K22: =K21/K20 -> 0.22 | L22: =L21/L20 -> 0.22 | M22: =M21/M20 -> 0.22 | N22: =N21/N20 -> 0.22 | O22: =O21/O20 -> 0.22 | P22: =P21/P20 -> 0.22 | Q22: =Q21/Q20 -> 0.22 | ... S22: =S21/S20 -> 0.22
B23: Net income | E23: =E20-E21 -> 725.694 | F23: =F20-F21 -> 540.159 | G23: =G20-G21 -> 792.566 | H23: =H20-H21 -> 950.072 | I23: =I20-I21 -> -81.198 | J23: =J20-J21 -> 636.78363 | K23: =K20-K21 -> 699.82968 | L23: =L20-L21 -> 753.92429 | ... S23: =S20-S21 -> 997.99596
B24: Diluted weighted-average shares (m) | E24: =Hist!E19 -> 63.718 | F24: =Hist!F19 -> 62.006 | G24: =Hist!G19 -> 61.952 | H24: =Hist!H19 -> 59.832 | I24: =Hist!I19 -> 54.208 | J24: =Equity!J20 -> 48.344673 | K24: =Equity!K20 -> 43.966801 | L24: =Equity!L20 -> 39.93889 | M24: =Equity!M20 -> 36.359366 | N24: =Equity!N20 -> 32.642195 | O24: =Equity!O20 -> 28.951515 | P24: =Equity!P20 -> 25.866868 | Q24: =Equity!Q20 -> 23.166982 | ... S24: =Equity!S20 -> 18.718461
B25: Diluted EPS (US$) | E25: =E23/E24 -> 11.389152 | F25: =F23/F24 -> 8.7113989 | G25: =G23/G24 -> 12.793227 | H25: =H23/H24 -> 15.878995 | I25: =I23/I24 -> -1.497897 | J25: =J23/J24 -> 13.171743 | K25: =K23/K24 -> 15.91723 | L25: =L23/L24 -> 18.876946 | ... S25: =S23/S24 -> 53.316132
B26: SG&A build (forecast)
B27: Crocs brand SG&A | E27: =Hist!E92 -> 0 | F27: =Hist!F92 -> 645.726 | G27: =Hist!G92 -> 727.954 | H27: =Hist!H92 -> 837.228 | I27: =Hist!I92 -> 926.681 | J27: =Rev_Build!J17*Inputs!J63 -> 937.57222 | K27: =Rev_Build!K17*Inputs!K63 -> 972.93082 | L27: =Rev_Build!L17*Inputs!L63 -> 1014.2844 | M27: =Rev_Build!M17*Inputs!M63 -> 1055.0218 | N27: =Rev_Build!N17*Inputs!N63 -> 1093.6131 | O27: =Rev_Build!O17*Inputs!O63 -> 1136.4084 | P27: =Rev_Build!P17*Inputs!P63 -> 1178.1913 | Q27: =Rev_Build!Q17*Inputs!Q63 -> 1218.6066 | ... S27: =Rev_Build!S17*Inputs!S63 -> 1293.9617
B28: HEYDUDE SG&A | E28: =Hist!E96 -> 0 | F28: =Hist!F96 -> 154.44 | G28: =Hist!G96 -> 205.593 | H28: =Hist!H96 -> 250.406 | I28: =Hist!I96 -> 251.89 | J28: =Rev_Build!J24*Inputs!J67 -> 229.24191 | K28: =Rev_Build!K24*Inputs!K67 -> 225.50831 | L28: =Rev_Build!L24*Inputs!L67 -> 224.40054 | M28: =Rev_Build!M24*Inputs!M67 -> 225.76352 | N28: =Rev_Build!N24*Inputs!N67 -> 231.49569 | O28: =Rev_Build!O24*Inputs!O67 -> 237.35847 | P28: =Rev_Build!P24*Inputs!P67 -> 243.35234 | Q28: =Rev_Build!Q24*Inputs!Q67 -> 249.47812 | ... S28: =Rev_Build!S24*Inputs!S67 -> 262.13026
B29: Corporate / unallocated | J29: =J7*Inputs!J71 -> 287.28182 | K29: =K7*Inputs!K71 -> 297.35698 | L29: =L7*Inputs!L71 -> 309.63773 | M29: =M7*Inputs!M71 -> 322.43336 | N29: =N7*Inputs!N71 -> 334.97282 | O29: =O7*Inputs!O71 -> 347.37072 | P29: =P7*Inputs!P71 -> 359.5353 | Q29: =Q7*Inputs!Q71 -> 371.37464 | ... S29: =S7*Inputs!S71 -> 393.72271
B30: Restructuring & other charges (recurring) | E30: =Hist!E29-Hist!E28 -> 5.836 | F30: =Hist!F29-Hist!F28 -> 35.141 | G30: =Hist!G29-Hist!G28 -> 49.542 | H30: =Hist!H29-Hist!H28 -> 4.266 | I30: =Hist!I29-Hist!I28 -> 13.037 | J30: =J7*Inputs!J75 -> 24.624156 | K30: =K7*Inputs!K75 -> 16.991828 | L30: =L7*Inputs!L75 -> 17.693584 | M30: =M7*Inputs!M75 -> 18.424764 | N30: =N7*Inputs!N75 -> 19.141304 | O30: =O7*Inputs!O75 -> 19.849756 | P30: =P7*Inputs!P75 -> 20.544874 | Q30: =Q7*Inputs!Q75 -> 21.221408 | ... S30: =S7*Inputs!S75 -> 22.498441
B31: Adjusted metrics & EBITDA
B32: Depreciation & amortisation | E32: =Hist!E21 -> 31.976 | F32: =Hist!F21 -> 39.229 | G32: =Hist!G21 -> 54.304 | H32: =Hist!H21 -> 69.84 | I32: =Hist!I21 -> 79.282 | J32: =Fixed_Assets!J9+Fixed_Assets!J15 -> 77.28393 | K32: =Fixed_Assets!K9+Fixed_Assets!K15 -> 77.686442 | L32: =Fixed_Assets!L9+Fixed_Assets!L15 -> 78.243042 | M32: =Fixed_Assets!M9+Fixed_Assets!M15 -> 78.98024 | N32: =Fixed_Assets!N9+Fixed_Assets!N15 -> 79.806567 | O32: =Fixed_Assets!O9+Fixed_Assets!O15 -> 82.288056 | P32: =Fixed_Assets!P9+Fixed_Assets!P15 -> 85.004579 | Q32: =Fixed_Assets!Q9+Fixed_Assets!Q15 -> 87.73581 | ... S32: =Fixed_Assets!S9+Fixed_Assets!S15 -> 93.160462
B33: EBITDA (before impairments) | E33: =E15+E32+E14 -> 715.04 | F33: =F15+F32+F14 -> 889.985 | G33: =G15+G32+G14 -> 1100.374 | H33: =H15+H32+H14 -> 1115.833 | I33: =I15+I32+I14 -> 966.912 | J33: =J15+J32+J14 -> 970.03191 | K33: =K15+K32+K14 -> 1031.2553 | L33: =L15+L32+L14 -> 1091.2857 | ... S33: =S15+S32+S14 -> 1410.3925
B34: EBITDA margin | E34: =E33/E7 -> 0.30908406 | F34: =F33/F7 -> 0.25034845 | G34: =G33/G7 -> 0.27770763 | H34: =H33/H7 -> 0.27201453 | I34: =I33/I7 -> 0.23929633 | J34: =J33/J7 -> 0.23636105 | K34: =K33/K7 -> 0.24276501 | L34: =L33/L7 -> 0.24670765 | ... S34: =S33/S7 -> 0.25075382
B35: Analyst-adjusted EBIT | E35: =Hist!E28 -> 689.426 | F35: =Hist!F28 -> 951.191 | G35: =Hist!G28 -> 1049.095 | H35: =Hist!H28 -> 1045.992 | I35: =Hist!I28 -> 887.63 | J35: =J15+J14 -> 892.74798 | K35: =K15+K14 -> 953.56887 | L35: =L15+L14 -> 1013.0426 | M35: =M15+M14 -> 1066.2924 | N35: =N15+N14 -> 1114.8917 | O35: =O15+O14 -> 1158.0022 | P35: =P15+P14 -> 1200.1365 | Q35: =Q15+Q14 -> 1240.9449 | ... S35: =S15+S14 -> 1317.232
B36: analyst EBIT margin | E36: =E35/E7 -> 0.29801212 | F36: =F35/F7 -> 0.2675654 | G36: =G35/G7 -> 0.26476606 | H36: =H35/H7 -> 0.2549889 | I36: =I35/I7 -> 0.21967522 | J36: =J35/J7 -> 0.21752981 | K36: =K35/K7 -> 0.22447706 | L36: =L35/L7 -> 0.2290192 | ... S36: =S35/S7 -> 0.23419081
B37: Management non-GAAP EBIT | E37: =Hist!E29 -> 695.262 | F37: =Hist!F29 -> 986.332 | G37: =Hist!G29 -> 1098.637 | H37: =Hist!H29 -> 1050.258 | I37: =Hist!I29 -> 900.667 | J37: =J35+J30 -> 917.37214 | K37: =K35+K30 -> 970.5607 | L37: =L35+L30 -> 1030.7362 | M37: =M35+M30 -> 1084.7171 | N37: =N35+N30 -> 1134.033 | O37: =O35+O30 -> 1177.8519 | P37: =P35+P30 -> 1220.6814 | Q37: =Q35+Q30 -> 1262.1663 | ... S37: =S35+S30 -> 1339.7304
B38: management EBIT margin | E38: =E37/E7 -> 0.30053479 | F38: =F37/F7 -> 0.2774504 | G38: =G37/G7 -> 0.27726925 | H38: =H37/H7 -> 0.25602885 | I38: =I37/I7 -> 0.22290168 | J38: =J37/J7 -> 0.22352981 | K38: =K37/K7 -> 0.22847706 | L38: =L37/L7 -> 0.2330192 | ... S38: =S37/S7 -> 0.23819081
B39: Adjusted diluted EPS - management basis (US$) | E39: =Hist!E30/E24 -> 8.3153269 | F39: =Hist!F30/F24 -> 10.923588 | G39: =Hist!G30/G24 -> 12.034785 | H39: =Hist!H30/H24 -> 13.167903 | I39: =Hist!I30/I24 -> 12.597403 | J39: =(J37+J17-J18+J19)*(1-Inputs!J103)/J24 -> 14.444715 | K39: =(K37+K17-K18+K19)*(1-Inputs!K103)/K24 -> 17.050403 | L39: =(L37+L17-L18+L19)*(1-Inputs!L103)/L24 -> 20.208268 | M39: =(M37+M17-M18+M19)*(1-Inputs!M103)/M24 -> 23.661987 | N39: =(N37+N17-N18+N19)*(1-Inputs!N103)/N24 -> 27.708377 | O39: =(O37+O17-O18+O19)*(1-Inputs!O103)/O24 -> 32.371897 | P39: =(P37+P17-P18+P19)*(1-Inputs!P103)/P24 -> 37.499852 | Q39: =(Q37+Q17-Q18+Q19)*(1-Inputs!Q103)/Q24 -> 43.338463 | ... S39: =(S37+S17-S18+S19)*(1-Inputs!S103)/S24 -> 57.035882
B40: growth | F40: =IFERROR(F39/E39-1,"n.m.") -> 0.3136691 | G40: =IFERROR(G39/F39-1,"n.m.") -> 0.10172454 | H40: =IFERROR(H39/G39-1,"n.m.") -> 0.094153611 | I40: =IFERROR(I39/H39-1,"n.m.") -> -0.04332511 | J40: =J39/I39-1 -> 0.14664232 | K40: =K39/J39-1 -> 0.18039042 | L40: =L39/K39-1 -> 0.18520766 | M40: =M39/L39-1 -> 0.17090623 | N40: =N39/M39-1 -> 0.17100801 | O40: =O39/N39-1 -> 0.16830725 | P40: =P39/O39-1 -> 0.15840761 | Q40: =Q39/P39-1 -> 0.1556969 | ... S40: =S39/R39-1 -> 0.14422413
B41: Segment EBIT
B42: Crocs brand segment EBIT | E42: =Hist!E93 -> 861.394 | F42: =Hist!F93 -> 852.025 | G42: =Hist!G93 -> 1079.33 | H42: =Hist!H93 -> 1182.012 | I42: =Hist!I93 -> 1111.679 | J42: =Rev_Build!J17*(Inputs!J55-Inputs!J63) -> 1142.1334 | K42: =Rev_Build!K17*(Inputs!K55-Inputs!K63) -> 1195.0611 | L42: =Rev_Build!L17*(Inputs!L55-Inputs!L63) -> 1256.2237 | M42: =Rev_Build!M17*(Inputs!M55-Inputs!M63) -> 1317.5618 | N42: =Rev_Build!N17*(Inputs!N55-Inputs!N63) -> 1377.1425 | O42: =Rev_Build!O17*(Inputs!O55-Inputs!O63) -> 1431.0328 | P42: =Rev_Build!P17*(Inputs!P55-Inputs!P63) -> 1483.6483 | Q42: =Rev_Build!Q17*(Inputs!Q55-Inputs!Q63) -> 1534.5417 | ... S42: =Rev_Build!S17*(Inputs!S55-Inputs!S63) -> 1629.4332
...

Sheet BS
B1: Balance sheet
B2: Crocs, Inc. (NASDAQ: CROX) | US$ millions unless stated
B4: Fiscal year ending 31-Dec | C4: Unit | E4: FY2021A | F4: FY2022A | G4: FY2023A | H4: FY2024A | I4: FY2025A | J4: FY2026E | K4: FY2027E | L4: FY2028E | M4: FY2029E | N4: FY2030E | O4: FY2031E | P4: FY2032E | Q4: FY2033E | R4: FY2034E | S4: FY2035E
B6: Assets
B7: Cash & equivalents | E7: =Hist!E32 -> 213.197 | F7: =Hist!F32 -> 191.629 | G7: =Hist!G32 -> 149.288 | H7: =Hist!H32 -> 180.485 | I7: =Hist!I32 -> 130.354 | J7: =CF!J35 -> 150 | K7: =CF!K35 -> 150 | L7: =CF!L35 -> 150 | M7: =CF!M35 -> 218.81211 | N7: =CF!N35 -> 150 | O7: =CF!O35 -> 150 | P7: =CF!P35 -> 150 | Q7: =CF!Q35 -> 150 | ... S7: =CF!S35 -> 150
B8: Accounts receivable | E8: =Hist!E33 -> 182.629 | F8: =Hist!F33 -> 295.594 | G8: =Hist!G33 -> 305.747 | H8: =Hist!H33 -> 257.657 | I8: =Hist!I33 -> 278.191 | J8: =NWC!J7 -> 281.09767 | K8: =NWC!K7 -> 290.95595 | L8: =NWC!L7 -> 302.97234 | M8: =NWC!M7 -> 315.49253 | N8: =NWC!N7 -> 327.76206 | O8: =NWC!O7 -> 339.89308 | P8: =NWC!P7 -> 351.79579 | Q8: =NWC!Q7 -> 363.38027 | ... S8: =NWC!S7 -> 385.24727
B9: Inventories | E9: =Hist!E34 -> 213.52 | F9: =Hist!F34 -> 471.551 | G9: =Hist!G34 -> 385.054 | H9: =Hist!H34 -> 356.254 | I9: =Hist!I34 -> 368.687 | J9: =NWC!J9 -> 379.73872 | K9: =NWC!K9 -> 390.4877 | L9: =NWC!L9 -> 404.23831 | M9: =NWC!M9 -> 420.43947 | N9: =NWC!N9 -> 436.42988 | O9: =NWC!O9 -> 452.26288 | P9: =NWC!P9 -> 467.82646 | Q9: =NWC!Q9 -> 483.00849 | ... S9: =NWC!S9 -> 511.79509
B10: Income taxes receivable | E10: =Hist!E35 -> 22.301 | F10: =Hist!F35 -> 14.752 | G10: =Hist!G35 -> 4.413 | H10: =Hist!H35 -> 4.046 | I10: =Hist!I35 -> 32.782 | J10: =NWC!J12 -> 32.782 | K10: =NWC!K12 -> 32.782 | L10: =NWC!L12 -> 32.782 | M10: =NWC!M12 -> 32.782 | N10: =NWC!N12 -> 32.782 | O10: =NWC!O12 -> 32.782 | P10: =NWC!P12 -> 32.782 | Q10: =NWC!Q12 -> 32.782 | ... S10: =NWC!S12 -> 32.782
B11: Prepaid & other current assets | E11: =Hist!E36 -> 34.922 | F11: =Hist!F36 -> 52.449 | G11: =Hist!G36 -> 66.202 | H11: =Hist!H36 -> 73.827 | I11: =Hist!I36 -> 75.869 | J11: =NWC!J11 -> 77.976494 | K11: =NWC!K11 -> 80.711182 | L11: =NWC!L11 -> 84.044526 | M11: =NWC!M11 -> 87.517627 | N11: =NWC!N11 -> 90.921195 | O11: =NWC!O11 -> 94.286339 | P11: =NWC!P11 -> 97.588152 | Q11: =NWC!Q11 -> 100.80169 | ... S11: =NWC!S11 -> 106.86759
B12: Total current assets | E12: =E7+E8+E9+E10+E11 -> 666.569 | F12: =F7+F8+F9+F10+F11 -> 1025.975 | G12: =G7+G8+G9+G10+G11 -> 910.704 | H12: =H7+H8+H9+H10+H11 -> 872.269 | I12: =I7+I8+I9+I10+I11 -> 885.883 | J12: =J7+J8+J9+J10+J11 -> 921.59488 | K12: =K7+K8+K9+K10+K11 -> 944.93683 | L12: =L7+L8+L9+L10+L11 -> 974.03717 | ... S12: =S7+S8+S9+S10+S11 -> 1186.6919
B13: PP&E, net | E13: =Hist!E38 -> 108.398 | F13: =Hist!F38 -> 181.529 | G13: =Hist!G38 -> 238.315 | H13: =Hist!H38 -> 244.335 | I13: =Hist!I38 -> 238.191 | J13: =Fixed_Assets!J11 -> 249.07149 | K13: =Fixed_Assets!K11 -> 259.75235 | L13: =Fixed_Assets!L11 -> 270.78365 | M13: =Fixed_Assets!M11 -> 282.20247 | N13: =Fixed_Assets!N11 -> 293.86111 | O13: =Fixed_Assets!O11 -> 305.67208 | P13: =Fixed_Assets!P11 -> 317.547 | Q13: =Fixed_Assets!Q11 -> 329.39682 | ... S13: =Fixed_Assets!S11 -> 352.66574
B14: Operating lease ROU assets | E14: =Hist!E39 -> 160.768 | F14: =Hist!F39 -> 239.905 | G14: =Hist!G39 -> 287.44 | H14: =Hist!H39 -> 307.228 | I14: =Hist!I39 -> 338.669 | J14: =Fixed_Assets!J22 -> 344.78725 | K14: =Fixed_Assets!K22 -> 356.87917 | L14: =Fixed_Assets!L22 -> 371.61816 | M14: =Fixed_Assets!M22 -> 386.97511 | N14: =Fixed_Assets!N22 -> 402.0246 | O14: =Fixed_Assets!O22 -> 416.9042 | P14: =Fixed_Assets!P22 -> 431.50377 | Q14: =Fixed_Assets!Q22 -> 445.713 | ... S14: =Fixed_Assets!S22 -> 472.5345
B15: Goodwill | E15: =Hist!E40 -> 1.6 | F15: =Hist!F40 -> 714.814 | G15: =Hist!G40 -> 711.588 | H15: =Hist!H40 -> 711.491 | I15: =Hist!I40 -> 404.689 | J15: =Fixed_Assets!J19 -> 404.689 | K15: =Fixed_Assets!K19 -> 404.689 | L15: =Fixed_Assets!L19 -> 404.689 | M15: =Fixed_Assets!M19 -> 404.689 | N15: =Fixed_Assets!N19 -> 404.689 | O15: =Fixed_Assets!O19 -> 404.689 | P15: =Fixed_Assets!P19 -> 404.689 | Q15: =Fixed_Assets!Q19 -> 404.689 | ... S15: =Fixed_Assets!S19 -> 404.689
B16: Intangible assets, net | E16: =Hist!E41 -> 28.802 | F16: =Hist!F41 -> 1800.167 | G16: =Hist!G41 -> 1792.562 | H16: =Hist!H41 -> 1777.08 | I16: =Hist!I41 -> 1324.68 | J16: =Fixed_Assets!J18 -> 1302.18 | K16: =Fixed_Assets!K18 -> 1281.78 | L16: =Fixed_Assets!L18 -> 1263.28 | M16: =Fixed_Assets!M18 -> 1246.58 | N16: =Fixed_Assets!N18 -> 1231.68 | O16: =Fixed_Assets!O18 -> 1216.98 | P16: =Fixed_Assets!P18 -> 1202.28 | Q16: =Fixed_Assets!Q18 -> 1187.58 | ... S16: =Fixed_Assets!S18 -> 1158.18
B17: Deferred tax assets | E17: =Hist!E43 -> 567.201 | F17: =Hist!F43 -> 528.278 | G17: =Hist!G43 -> 667.972 | H17: =Hist!H43 -> 872.35 | I17: =Hist!I43 -> 935.054 | J17: =Tax!J15 -> 893.70441 | K17: =Tax!K15 -> 857.81571 | L17: =Tax!L15 -> 819.15293 | M17: =Tax!M15 -> 777.92236 | N17: =Tax!N15 -> 734.56791 | O17: =Tax!O15 -> 689.64407 | P17: =Tax!P15 -> 643.14861 | Q17: =Tax!Q15 -> 595.02081 | ... S17: =Tax!S15 -> 494.14812
B18: Other non-current assets | E18: =Hist!E44 -> 11.73 | F18: =Hist!F44 -> 11.129 | G18: =Hist!G44 -> 35.253 | H18: =Hist!H44 -> 27.4 | I18: =Hist!I44 -> 47.584 | J18: =I18 -> 47.584 | K18: =J18 -> 47.584 | L18: =K18 -> 47.584 | M18: =L18 -> 47.584 | N18: =M18 -> 47.584 | O18: =N18 -> 47.584 | P18: =O18 -> 47.584 | Q18: =P18 -> 47.584 | ... S18: =R18 -> 47.584
B19: Total assets | E19: =E12+E13+E14+E15+E16+E17+E18 -> 1545.068 | F19: =F12+F13+F14+F15+F16+F17+F18 -> 4501.797 | G19: =G12+G13+G14+G15+G16+G17+G18 -> 4643.834 | H19: =H12+H13+H14+H15+H16+H17+H18 -> 4812.153 | I19: =I12+I13+I14+I15+I16+I17+I18 -> 4174.75 | J19: =J12+J13+J14+J15+J16+J17+J18 -> 4163.611 | K19: =K12+K13+K14+K15+K16+K17+K18 -> 4153.4371 | L19: =L12+L13+L14+L15+L16+L17+L18 -> 4151.1449 | ... S19: =S12+S13+S14+S15+S16+S17+S18 -> 4116.4933
B20: Liabilities
B21: Accounts payable | E21: =Hist!E46 -> 162.145 | F21: =Hist!F46 -> 230.821 | G21: =Hist!G46 -> 260.978 | H21: =Hist!H46 -> 264.901 | I21: =Hist!I46 -> 266.09 | J21: =NWC!J14 -> 270.56384 | K21: =NWC!K14 -> 278.22248 | L21: =NWC!L14 -> 288.01979 | M21: =NWC!M14 -> 299.56312 | N21: =NWC!N14 -> 310.95629 | O21: =NWC!O14 -> 322.2373 | P21: =NWC!P14 -> 333.32635 | Q21: =NWC!Q14 -> 344.14355 | ... S21: =NWC!S14 -> 364.654
B22: Accrued expenses & other | E22: =Hist!E47 -> 166.887 | F22: =Hist!F47 -> 239.424 | G22: =Hist!G47 -> 285.771 | H22: =Hist!H47 -> 298.068 | I22: =Hist!I47 -> 300.959 | J22: =NWC!J16 -> 303.69792 | K22: =NWC!K16 -> 314.34881 | L22: =NWC!L16 -> 327.33131 | M22: =NWC!M16 -> 340.85813 | N22: =NWC!N16 -> 354.11413 | O22: =NWC!O16 -> 367.22048 | P22: =NWC!P16 -> 380.08017 | Q22: =NWC!Q16 -> 392.59605 | ... S22: =NWC!S16 -> 416.22115
B23: Income taxes payable | E23: =Hist!E48 -> 16.279 | F23: =Hist!F48 -> 89.211 | G23: =Hist!G48 -> 65.952 | H23: =Hist!H48 -> 108.688 | I23: =Hist!I48 -> 47.308 | J23: =NWC!J17 -> 47.308 | K23: =NWC!K17 -> 47.308 | L23: =NWC!L17 -> 47.308 | M23: =NWC!M17 -> 47.308 | N23: =NWC!N17 -> 47.308 | O23: =NWC!O17 -> 47.308 | P23: =NWC!P17 -> 47.308 | Q23: =NWC!Q17 -> 47.308 | ... S23: =NWC!S17 -> 47.308
B24: Operating lease liabilities - current | E24: =Hist!E49 -> 42.932 | F24: =Hist!F49 -> 57.456 | G24: =Hist!G49 -> 62.267 | H24: =Hist!H49 -> 68.551 | I24: =Hist!I49 -> 85.772 | J24: =Fixed_Assets!J23 -> 87.321521 | K24: =Fixed_Assets!K23 -> 90.383946 | L24: =Fixed_Assets!L23 -> 94.116772 | M24: =Fixed_Assets!M23 -> 98.006104 | N24: =Fixed_Assets!N23 -> 101.81757 | O24: =Fixed_Assets!O23 -> 105.58601 | P24: =Fixed_Assets!P23 -> 109.28352 | Q24: =Fixed_Assets!Q23 -> 112.88218 | ... S24: =Fixed_Assets!S23 -> 119.67505
B25: Current debt | E25: =Hist!E50 -> 0 | F25: =Hist!F50 -> 24.362 | G25: =Hist!G50 -> 23.328 | H25: =Hist!H50 -> 0 | I25: =Hist!I50 -> 0 | J25: 0 | K25: 0 | L25: 0 | M25: 0 | N25: 0 | O25: 0 | P25: 0 | Q25: 0 | R25: 0 | S25: 0
